Workbook

Sheet Summary
C2: Arm Holdings short valuation
C3: USD billions, except shares in billions and per-share amounts. FY ends 31 March.
C4: Selected case | E4: =CHOOSE(Assumptions!$E$5,"Bear","Base","Bull") -> Base
C8: Reference price | E8: =Assumptions!E8 -> 227.8
C9: =IF(Assumptions!E5=2,"12-month trading target","Fixed-multiple price indication") -> 12-month trading target | E9: =Comps!E23 -> 125
C10: Gross price downside | E10: =Comps!E24 -> 0.45127305
C11: Net notional return after borrow | E11: ='Short return'!E16 -> 0.39127305
C12: Illustrative collateral XIRR | E12: ='Short return'!E20 -> 0.75259844
C14: Current DCF per share | E14: =DCF!E46 -> 80.779177
C15: Target-date DCF per share | E15: =DCF!E53 -> 89.634135
C16: Terminal value / enterprise value | E16: =DCF!E54 -> 0.66815428
C18: Reference date | E18: =Assumptions!E9 -> 46311
C19: Target date | E19: =Assumptions!E10 -> 46676
C20: Eligibility market cap proxy ($bn) | E20: =Sources!E12*Sources!E13 -> 313.63956
C21: Price-implied revenue multiplier | E21: =DCF!E57 -> 2.9285866
C23: Net return at active DCF value | E23: =1-DCF!E53/Assumptions!E8-Assumptions!E19*'Short return'!E11-'Short return'!E12/Assumptions!E8 -> 0.54652267
C24: SHORT. The base forecast grants strong growth; the recommendation depends mainly on valuation compression within one year.
C25: Change Assumptions E5 to compare Bear (1), Base (2) and Bull (3). Each selection recalculates the same linked statements and valuation.
C26: The $125 base target remains a judgment. Stronger CPU execution and a sustained premium multiple can invalidate the short.
C27: The fixed-multiple indication assumes rerating in every case. Active DCF and borrow table assesses bull-case losses.
C29: Annual forecast
E30: FY2027E | F30: FY2028E | G30: FY2029E | H30: FY2030E | I30: FY2031E | J30: FY2032E | K30: FY2033E | L30: FY2034E | M30: FY2035E | N30: FY2036E
C31: Revenue | E31: =Operating!E13 -> 6.06 | F31: =Operating!F13 -> 8.25 | G31: =Operating!G13 -> 12 | H31: =Operating!H13 -> 18 | I31: =Operating!I13 -> 25 | J31: =Operating!J13 -> 30.1 | K31: =Operating!K13 -> 34.2 | L31: =Operating!L13 -> 38.3 | ... N31: =Operating!N13 -> 46.5
C32: Economic operating income | E32: =Operating!E26 -> 1.0318 | F32: =Operating!F26 -> 2.091 | G32: =Operating!G26 -> 3.76 | H32: =Operating!H26 -> 6.498 | I32: =Operating!I26 -> 9 | J32: =Operating!J26 -> 10.978 | K32: =Operating!K26 -> 12.556 | L32: =Operating!L26 -> 14.134 | ... N32: =Operating!N26 -> 17.29
C33: Adjusted operating EPS proxy | E33: =Operating!E32 -> 1.9222926 | F33: =Operating!F32 -> 2.8403889 | G33: =Operating!G32 -> 4.2214815 | H33: =Operating!H32 -> 6.4142222 | I33: =Operating!I32 -> 8.3518519 | J33: =Operating!J32 -> 10.005519 | K33: =Operating!K32 -> 11.355481 | L33: =Operating!L32 -> 12.705444 | ... N33: =Operating!N32 -> 15.40537
C34: Cash from operations | E34: =Statements!E99 -> 2.2544052 | F34: =Statements!F99 -> 2.887654 | G34: =Statements!G99 -> 4.4473818 | H34: =Statements!H99 -> 6.3684736 | I34: =Statements!I99 -> 8.5390909 | J34: =Statements!J99 -> 10.90096 | K34: =Statements!K99 -> 12.714829 | L34: =Statements!L99 -> 14.328698 | ... N34: =Statements!N99 -> 17.556436
C35: Ending cash | E35: =Statements!E104 -> 2.928832 | F35: =Statements!F104 -> 3.870236 | G35: =Statements!G104 -> 5.954436 | H35: =Statements!H104 -> 9.362796 | I35: =Statements!I104 -> 14.342796 | J35: =Statements!J104 -> 21.120756 | K35: =Statements!K104 -> 29.228676 | L35: =Statements!L104 -> 38.466556 | ... N35: =Statements!N104 -> 60.332196
H39: Fiscal year | I39: IP / total | J39: CPU | K39: Revenue
H40: FY26A | I40: =Historical!G9 -> 4.92 | J40: 0 | K40: =SUM(I40:J40) -> 4.92
H41: FY27E | I41: =Operating!E11 -> 5.76 | J41: =Operating!E12 -> 0.3 | K41: =SUM(I41:J41) -> 6.06
H42: FY28E | I42: =Operating!F11 -> 6.95 | J42: =Operating!F12 -> 1.3 | K42: =SUM(I42:J42) -> 8.25
H43: FY29E | I43: =Operating!G11 -> 8 | J43: =Operating!G12 -> 4 | K43: =SUM(I43:J43) -> 12
H44: FY31E | I44: =Operating!I11 -> 10 | J44: =Operating!I12 -> 15 | K44: =SUM(I44:J44) -> 25

Sheet Assumptions
C2: Assumptions
C3: USD billions, except shares in billions and per-share amounts. FY ends 31 March.
C4: Selected case | E4: =CHOOSE(Assumptions!$E$5,"Bear","Base","Bull") -> Base
C5: Case number: 1 Bear, 2 Base, 3 Bull | E5: 2
C8: Reference price | E8: =Sources!E8 -> 227.8 | G8: Factual inputs link to Sources. Grey control selects one case through one forecast.
C9: Reference date | E9: =Sources!E9 -> 46311
C10: Target date | E10: =Sources!E10 -> 46676
C11: Opening balance sheet date | E11: =Sources!E11 -> 46203
C15: Valuation diluted shares | E15: 1.08
C16: Terminal growth | E16: 0.03 | G16: 3% long-run growth and 30% ROIC are valuation assumptions, not guidance.
C17: Terminal ROIC | E17: 0.3
C18: Equity investment recovery | E18: 0.5
C19: Annual borrow fee assumption | E19: 0.06 | G19: Borrow is unquoted. Sensitivities include 3%, 6%, 12% and 20%; recall remains a risk.
C20: Initial cash collateral / notional | E20: 0.5
C21: Annual dividend per share | E21: 0
C22: Illustrative CPU selling price ($) | E22: 1000
C23: Q2 FY27 revenue midpoint | E23: =Sources!E15 -> 1.38
C24: Q2 gross margin assumption | E24: 0.98
C25: Q2 adjusted operating expense | E25: =Sources!E16 -> 0.78
C26: Q2 compensation adjustment | E26: 0.4
C27: Q3 share of FY27 remainder | E27: 0.47
C28: SBC offset repurchases / SBC | E28: 1 | G28: 100% offset repurchases keep economic share count flat. This is not a buyback announcement.
C29: Q1 FY28 share of FY28 revenue | E29: 0.22
C30: Q2 FY28 share of FY28 revenue | E30: 0.235
C31: Street EPS target multiple | E31: 40
C32: Own EPS target multiple | E32: 45
C33: Q3 FY28 share of FY28 revenue | E33: 0.26
C34: DreamBig acquisition cash paid | E34: =Sources!E17 -> 0.265 | G34: Known July cash acquisition. Provisional goodwill allocation pending final purchase accounting.
C35: Assumed R&D share of operating costs | E35: 0.75 | G35: Forecast expense allocation only. Historical R&D is reported separately.
C36: Effective tax rate | E36: 0.18 | G36: Normalized tax; no recurring investment gains or interest income forecast.
C37: Financial debt beyond grouped leases | E37: 0
E39: FY2027E | F39: FY2028E | G39: FY2029E | H39: FY2030E | I39: FY2031E | J39: FY2032E | K39: FY2033E | L39: FY2034E | M39: FY2035E | N39: FY2036E
C40: IP revenue - selected | E40: =IF(COUNT(INDEX(E41:E43,$E$5))=1,INDEX(E41:E43,$E$5),NA()) -> 5.76 | F40: =IF(COUNT(INDEX(F41:F43,$E$5))=1,INDEX(F41:F43,$E$5),NA()) -> 6.95 | G40: =IF(COUNT(INDEX(G41:G43,$E$5))=1,INDEX(G41:G43,$E$5),NA()) -> 8 | H40: =IF(COUNT(INDEX(H41:H43,$E$5))=1,INDEX(H41:H43,$E$5),NA()) -> 9.1 | I40: =IF(COUNT(INDEX(I41:I43,$E$5))=1,INDEX(I41:I43,$E$5),NA()) -> 10 | J40: =IF(COUNT(INDEX(J41:J43,$E$5))=1,INDEX(J41:J43,$E$5),NA()) -> 11.1 | K40: =IF(COUNT(INDEX(K41:K43,$E$5))=1,INDEX(K41:K43,$E$5),NA()) -> 12.2 | L40: =IF(COUNT(INDEX(L41:L43,$E$5))=1,INDEX(L41:L43,$E$5),NA()) -> 13.3 | ... N40: =IF(COUNT(INDEX(N41:N43,$E$5))=1,INDEX(N41:N43,$E$5),NA()) -> 15.5
C41: Bear | E41: 5.5 | F41: 6 | G41: 6.8 | H41: 7.5 | I41: 8.2 | J41: 8.8 | K41: 9.4 | L41: 10 | M41: 10.5 | N41: 11
C42: Base | E42: 5.76 | F42: 6.95 | G42: 8 | H42: 9.1 | I42: 10 | J42: 11.1 | K42: 12.2 | L42: 13.3 | M42: 14.4 | N42: 15.5
C43: Bull | E43: 6 | F43: 7.5 | G43: 9 | H43: 10.5 | I43: 12 | J43: 14 | K43: 16 | L43: 18 | M43: 20 | N43: 22
C45: CPU revenue - selected | E45: =IF(COUNT(INDEX(E46:E48,$E$5))=1,INDEX(E46:E48,$E$5),NA()) -> 0.3 | F45: =IF(COUNT(INDEX(F46:F48,$E$5))=1,INDEX(F46:F48,$E$5),NA()) -> 1.3 | G45: =IF(COUNT(INDEX(G46:G48,$E$5))=1,INDEX(G46:G48,$E$5),NA()) -> 4 | H45: =IF(COUNT(INDEX(H46:H48,$E$5))=1,INDEX(H46:H48,$E$5),NA()) -> 8.9 | I45: =IF(COUNT(INDEX(I46:I48,$E$5))=1,INDEX(I46:I48,$E$5),NA()) -> 15 | J45: =IF(COUNT(INDEX(J46:J48,$E$5))=1,INDEX(J46:J48,$E$5),NA()) -> 19 | K45: =IF(COUNT(INDEX(K46:K48,$E$5))=1,INDEX(K46:K48,$E$5),NA()) -> 22 | L45: =IF(COUNT(INDEX(L46:L48,$E$5))=1,INDEX(L46:L48,$E$5),NA()) -> 25 | ... N45: =IF(COUNT(INDEX(N46:N48,$E$5))=1,INDEX(N46:N48,$E$5),NA()) -> 31
C46: Bear | E46: 0.15 | F46: 0.6 | G46: 1.5 | H46: 3 | I46: 5 | J46: 6 | K46: 7 | L46: 8 | M46: 9 | N46: 10
C47: Base | E47: 0.3 | F47: 1.3 | G47: 4 | H47: 8.9 | I47: 15 | J47: 19 | K47: 22 | L47: 25 | M47: 28 | N47: 31
C48: Bull | E48: 0.6 | F48: 2.5 | G48: 7 | H48: 14.5 | I48: 23 | J48: 33 | K48: 44 | L48: 55 | M48: 66 | N48: 78
...

Sheet Operating
C2: Operating
C3: USD billions, except shares in billions and per-share amounts. FY ends 31 March.
C4: Selected case | E4: =CHOOSE(Assumptions!$E$5,"Bear","Base","Bull") -> Base
E7: FY2027E | F7: FY2028E | G7: FY2029E | H7: FY2030E | I7: FY2031E | J7: FY2032E | K7: FY2033E | L7: FY2034E | M7: FY2035E | N7: FY2036E
C9: Royalty revenue | E9: =Assumptions!E40*Assumptions!E95 -> 3.4 | F9: =Assumptions!F40*Assumptions!F95 -> 4.2 | G9: =Assumptions!G40*Assumptions!G95 -> 4.9 | H9: =Assumptions!H40*Assumptions!H95 -> 5.6 | I9: =Assumptions!I40*Assumptions!I95 -> 6.2 | J9: =Assumptions!J40*Assumptions!J95 -> 6.882 | K9: =Assumptions!K40*Assumptions!K95 -> 7.564 | L9: =Assumptions!L40*Assumptions!L95 -> 8.246 | ... N9: =Assumptions!N40*Assumptions!N95 -> 9.61
C10: License and other IP revenue | E10: =E11-E9 -> 2.36 | F10: =F11-F9 -> 2.75 | G10: =G11-G9 -> 3.1 | H10: =H11-H9 -> 3.5 | I10: =I11-I9 -> 3.8 | J10: =J11-J9 -> 4.218 | K10: =K11-K9 -> 4.636 | L10: =L11-L9 -> 5.054 | ... N10: =N11-N9 -> 5.89
C11: Total IP revenue | E11: =Assumptions!E40 -> 5.76 | F11: =Assumptions!F40 -> 6.95 | G11: =Assumptions!G40 -> 8 | H11: =Assumptions!H40 -> 9.1 | I11: =Assumptions!I40 -> 10 | J11: =Assumptions!J40 -> 11.1 | K11: =Assumptions!K40 -> 12.2 | L11: =Assumptions!L40 -> 13.3 | ... N11: =Assumptions!N40 -> 15.5
C12: CPU revenue | E12: =Assumptions!E45 -> 0.3 | F12: =Assumptions!F45 -> 1.3 | G12: =Assumptions!G45 -> 4 | H12: =Assumptions!H45 -> 8.9 | I12: =Assumptions!I45 -> 15 | J12: =Assumptions!J45 -> 19 | K12: =Assumptions!K45 -> 22 | L12: =Assumptions!L45 -> 25 | ... N12: =Assumptions!N45 -> 31
C13: Total revenue | E13: =SUM(E11:E12) -> 6.06 | F13: =SUM(F11:F12) -> 8.25 | G13: =SUM(G11:G12) -> 12 | H13: =SUM(H11:H12) -> 18 | I13: =SUM(I11:I12) -> 25 | J13: =SUM(J11:J12) -> 30.1 | K13: =SUM(K11:K12) -> 34.2 | L13: =SUM(L11:L12) -> 38.3 | ... N13: =SUM(N11:N12) -> 46.5
C14: Revenue growth | E14: =E13/Historical!G9-1 -> 0.23170732 | F14: =F13/E13-1 -> 0.36138614 | G14: =G13/F13-1 -> 0.45454545 | H14: =H13/G13-1 -> 0.5 | I14: =I13/H13-1 -> 0.38888889 | J14: =J13/I13-1 -> 0.204 | K14: =K13/J13-1 -> 0.13621262 | L14: =L13/K13-1 -> 0.11988304 | M14: =M13/L13-1 -> 0.10704961 | N14: =N13/M13-1 -> 0.096698113
C16: IP gross margin | E16: =Assumptions!E50 -> 0.98 | F16: =Assumptions!F50 -> 0.98 | G16: =Assumptions!G50 -> 0.98 | H16: =Assumptions!H50 -> 0.98 | I16: =Assumptions!I50 -> 0.98 | J16: =Assumptions!J50 -> 0.98 | K16: =Assumptions!K50 -> 0.98 | L16: =Assumptions!L50 -> 0.98 | ... N16: =Assumptions!N50 -> 0.98
C17: CPU gross margin | E17: =Assumptions!E55 -> 0.5 | F17: =Assumptions!F55 -> 0.5 | G17: =Assumptions!G55 -> 0.5 | H17: =Assumptions!H55 -> 0.5 | I17: =Assumptions!I55 -> 0.5 | J17: =Assumptions!J55 -> 0.5 | K17: =Assumptions!K55 -> 0.5 | L17: =Assumptions!L55 -> 0.5 | ... N17: =Assumptions!N55 -> 0.5
C18: IP gross profit | E18: =E11*E16 -> 5.6448 | F18: =F11*F16 -> 6.811 | G18: =G11*G16 -> 7.84 | H18: =H11*H16 -> 8.918 | I18: =I11*I16 -> 9.8 | J18: =J11*J16 -> 10.878 | K18: =K11*K16 -> 11.956 | L18: =L11*L16 -> 13.034 | ... N18: =N11*N16 -> 15.19
C19: CPU gross profit | E19: =E12*E17 -> 0.15 | F19: =F12*F17 -> 0.65 | G19: =G12*G17 -> 2 | H19: =H12*H17 -> 4.45 | I19: =I12*I17 -> 7.5 | J19: =J12*J17 -> 9.5 | K19: =K12*K17 -> 11 | L19: =L12*L17 -> 12.5 | ... N19: =N12*N17 -> 15.5
C20: Total gross profit | E20: =SUM(E18:E19) -> 5.7948 | F20: =SUM(F18:F19) -> 7.461 | G20: =SUM(G18:G19) -> 9.84 | H20: =SUM(H18:H19) -> 13.368 | I20: =SUM(I18:I19) -> 17.3 | J20: =SUM(J18:J19) -> 20.378 | K20: =SUM(K18:K19) -> 22.956 | L20: =SUM(L18:L19) -> 25.534 | ... N20: =SUM(N18:N19) -> 30.69
C21: Blended gross margin | E21: =E20/E13 -> 0.95623762 | F21: =F20/F13 -> 0.90436364 | G21: =G20/G13 -> 0.82 | H21: =H20/H13 -> 0.74266667 | I21: =I20/I13 -> 0.692 | J21: =J20/J13 -> 0.67700997 | K21: =K20/K13 -> 0.67122807 | L21: =L20/L13 -> 0.66668407 | ... N21: =N20/N13 -> 0.66
C23: Adjusted operating expense | E23: =Assumptions!E60 -> 3.263 | F23: =Assumptions!F60 -> 3.72 | G23: =Assumptions!G60 -> 4.28 | H23: =Assumptions!H60 -> 4.92 | I23: =Assumptions!I60 -> 6.3 | J23: =Assumptions!J60 -> 7.2 | K23: =Assumptions!K60 -> 8 | L23: =Assumptions!L60 -> 8.8 | ... N23: =Assumptions!N60 -> 10.4
C24: Compensation adjustment | E24: =Assumptions!E65 -> 1.5 | F24: =Assumptions!F65 -> 1.65 | G24: =Assumptions!G65 -> 1.8 | H24: =Assumptions!H65 -> 1.95 | I24: =Assumptions!I65 -> 2 | J24: =Assumptions!J65 -> 2.2 | K24: =Assumptions!K65 -> 2.4 | L24: =Assumptions!L65 -> 2.6 | ... N24: =Assumptions!N65 -> 3
C25: Total operating expense | E25: =SUM(E23:E24) -> 4.763 | F25: =SUM(F23:F24) -> 5.37 | G25: =SUM(G23:G24) -> 6.08 | H25: =SUM(H23:H24) -> 6.87 | I25: =SUM(I23:I24) -> 8.3 | J25: =SUM(J23:J24) -> 9.4 | K25: =SUM(K23:K24) -> 10.4 | L25: =SUM(L23:L24) -> 11.4 | ... N25: =SUM(N23:N24) -> 13.4
C26: Economic operating income | E26: =E20-E25 -> 1.0318 | F26: =F20-F25 -> 2.091 | G26: =G20-G25 -> 3.76 | H26: =H20-H25 -> 6.498 | I26: =I20-I25 -> 9 | J26: =J20-J25 -> 10.978 | K26: =K20-K25 -> 12.556 | L26: =L20-L25 -> 14.134 | ... N26: =N20-N25 -> 17.29
C27: Economic operating margin | E27: =E26/E13 -> 0.17026403 | F27: =F26/F13 -> 0.25345455 | G27: =G26/G13 -> 0.31333333 | H27: =H26/H13 -> 0.361 | I27: =I26/I13 -> 0.36 | J27: =J26/J13 -> 0.36471761 | K27: =K26/K13 -> 0.3671345 | L27: =L26/L13 -> 0.36903394 | ... N27: =N26/N13 -> 0.37182796
C28: Adjusted operating income | E28: =E20-E23 -> 2.5318 | F28: =F20-F23 -> 3.741 | G28: =G20-G23 -> 5.56 | H28: =H20-H23 -> 8.448 | I28: =I20-I23 -> 11 | J28: =J20-J23 -> 13.178 | K28: =K20-K23 -> 14.956 | L28: =L20-L23 -> 16.734 | ... N28: =N20-N23 -> 20.29
C30: Normalized economic net income | E30: =E26*(1-Assumptions!$E$36) -> 0.846076 | F30: =F26*(1-Assumptions!$E$36) -> 1.71462 | G30: =G26*(1-Assumptions!$E$36) -> 3.0832 | H30: =H26*(1-Assumptions!$E$36) -> 5.32836 | I30: =I26*(1-Assumptions!$E$36) -> 7.38 | J30: =J26*(1-Assumptions!$E$36) -> 9.00196 | K30: =K26*(1-Assumptions!$E$36) -> 10.29592 | L30: =L26*(1-Assumptions!$E$36) -> 11.58988 | ... N30: =N26*(1-Assumptions!$E$36) -> 14.1778
C31: Economic EPS | E31: =E30/Assumptions!$E$15 -> 0.7834037 | F31: =F30/Assumptions!$E$15 -> 1.5876111 | G31: =G30/Assumptions!$E$15 -> 2.8548148 | H31: =H30/Assumptions!$E$15 -> 4.9336667 | I31: =I30/Assumptions!$E$15 -> 6.8333333 | J31: =J30/Assumptions!$E$15 -> 8.3351481 | K31: =K30/Assumptions!$E$15 -> 9.5332593 | L31: =L30/Assumptions!$E$15 -> 10.73137 | ... N31: =N30/Assumptions!$E$15 -> 13.127593
C32: Adjusted operating EPS proxy | E32: =E28*(1-Assumptions!$E$36)/Assumptions!$E$15 -> 1.9222926 | F32: =F28*(1-Assumptions!$E$36)/Assumptions!$E$15 -> 2.8403889 | G32: =G28*(1-Assumptions!$E$36)/Assumptions!$E$15 -> 4.2214815 | H32: =H28*(1-Assumptions!$E$36)/Assumptions!$E$15 -> 6.4142222 | I32: =I28*(1-Assumptions!$E$36)/Assumptions!$E$15 -> 8.3518519 | J32: =J28*(1-Assumptions!$E$36)/Assumptions!$E$15 -> 10.005519 | K32: =K28*(1-Assumptions!$E$36)/Assumptions!$E$15 -> 11.355481 | L32: =L28*(1-Assumptions!$E$36)/Assumptions!$E$15 -> 12.705444 | ... N32: =N28*(1-Assumptions!$E$36)/Assumptions!$E$15 -> 15.40537
C34: CPU units at assumed ASP (millions) | E34: =E12*1000/Assumptions!$E$22 -> 0.3 | F34: =F12*1000/Assumptions!$E$22 -> 1.3 | G34: =G12*1000/Assumptions!$E$22 -> 4 | H34: =H12*1000/Assumptions!$E$22 -> 8.9 | I34: =I12*1000/Assumptions!$E$22 -> 15 | J34: =J12*1000/Assumptions!$E$22 -> 19 | K34: =K12*1000/Assumptions!$E$22 -> 22 | L34: =L12*1000/Assumptions!$E$22 -> 25 | ... N34: =N12*1000/Assumptions!$E$22 -> 31
C35: CPU share of $100bn reference TAM | E35: =E12/100 -> 0.003 | F35: =F12/100 -> 0.013 | G35: =G12/100 -> 0.04 | H35: =H12/100 -> 0.089 | I35: =I12/100 -> 0.15 | J35: =J12/100 -> 0.19 | K35: =K12/100 -> 0.22 | L35: =L12/100 -> 0.25 | ... N35: =N12/100 -> 0.31
C37: Non-cash SBC estimate | E37: =E24*Assumptions!E85 -> 1.1693182 | F37: =F24*Assumptions!F85 -> 1.28625 | G37: =G24*Assumptions!G85 -> 1.4031818 | H37: =H24*Assumptions!H85 -> 1.5201136 | I37: =I24*Assumptions!I85 -> 1.5590909 | J37: =J24*Assumptions!J85 -> 1.715 | K37: =K24*Assumptions!K85 -> 1.8709091 | L37: =L24*Assumptions!L85 -> 2.0268182 | ... N37: =N24*Assumptions!N85 -> 2.3386364
C38: Cash portion of adjustment | E38: =E24-E37 -> 0.33068182 | F38: =F24-F37 -> 0.36375 | G38: =G24-G37 -> 0.39681818 | H38: =H24-H37 -> 0.42988636 | I38: =I24-I37 -> 0.44090909 | J38: =J24-J37 -> 0.485 | K38: =K24-K37 -> 0.52909091 | L38: =L24-L37 -> 0.57318182 | ... N38: =N24-N37 -> 0.66136364
C41: FY27 reported Q1 is preserved in Statements. Normalized annual EPS applies 18% tax to the full year and excludes gains.
C42: Royalty/license split is analytical. Volume and ASP are not disclosed; the CPU-unit calculation is a feasibility check.
C43: FY31 base IP $10bn and CPU $15bn match management ambitions. Achieving them is not assured.
C47: Route | D47: Chip reference ($) | E47: Share / margin | F47: Gross profit ($)
C48: IP license | D48: 1000 | E48: 0.05 | F48: =D48*E48 -> 50
C49: CSS | D49: 1000 | E49: 0.1 | F49: =D49*E49 -> 100
C50: Own CPU | D50: 1000 | E50: 0.5 | F50: =D50*E50 -> 500
C62: Illustration from S5. These are not disclosed ASPs or contractual royalty rates.

Sheet Statements
C2: Statements
C3: USD billions, except shares in billions and per-share amounts. FY ends 31 March.
C4: Selected case | E4: =CHOOSE(Assumptions!$E$5,"Bear","Base","Bull") -> Base
E7: Q1 FY27A | F7: Q2 FY27E | G7: Q3 FY27E | H7: Q4 FY27E | I7: Q1 FY28E | J7: Q2 FY28E | K7: Q3 FY28E | L7: Q4 FY28E | M7: FY2029E | N7: FY2030E | O7: FY2031E | P7: FY2032E | Q7: FY2033E | R7: FY2034E | S7: FY2035E | T7: FY2036E
C8: Period duration (years) | E8: =0.25 -> 0.25 | F8: =0.25 -> 0.25 | G8: =0.25 -> 0.25 | H8: =0.25 -> 0.25 | I8: =0.25 -> 0.25 | J8: =0.25 -> 0.25 | K8: =0.25 -> 0.25 | L8: =0.25 -> 0.25 | M8: =1 -> 1 | N8: =1 -> 1 | O8: =1 -> 1 | P8: =1 -> 1 | Q8: =1 -> 1 | R8: =1 -> 1 | S8: =1 -> 1 | T8: =1 -> 1
C9: Revenue | E9: =Historical!H9 -> 1.289 | F9: =Assumptions!$E$23 -> 1.38 | G9: =(Operating!E13-$E$9-$F$9)*Assumptions!$E$27 -> 1.59377 | H9: =(Operating!E13-$E$9-$F$9)*(1-Assumptions!$E$27) -> 1.79723 | I9: =Operating!F13*Assumptions!$E$29 -> 1.815 | J9: =Operating!F13*Assumptions!$E$30 -> 1.93875 | K9: =Operating!F13*Assumptions!$E$33 -> 2.145 | L9: =Operating!F13*(1-SUM(Assumptions!$E$29:$E$30)-Assumptions!$E$33) -> 2.35125 | M9: =Operating!G13*1 -> 12 | N9: =Operating!H13*1 -> 18 | O9: =Operating!I13*1 -> 25 | P9: =Operating!J13*1 -> 30.1 | Q9: =Operating!K13*1 -> 34.2 | R9: =Operating!L13*1 -> 38.3 | S9: =Operating!M13*1 -> 42.4 | T9: =Operating!N13*1 -> 46.5
C10: Cost of sales | E10: =Historical!H10 -> 0.036 | F10: =F9-F11 -> 0.0276 | G10: =G9-G11 -> 0.094752 | H10: =H9-H11 -> 0.106848 | I10: =I9-I11 -> 0.17358 | J10: =J9-J11 -> 0.185415 | K10: =K9-K11 -> 0.20514 | L10: =L9-L11 -> 0.224865 | M10: =M9-M11 -> 2.16 | ... T10: =T9-T11 -> 15.81
C11: Gross profit | E11: =Historical!H11 -> 1.253 | F11: =F9*Assumptions!$E$24 -> 1.3524 | G11: =(Operating!E20-$E$11-$F$11)*Assumptions!$E$27 -> 1.499018 | H11: =(Operating!E20-$E$11-$F$11)*(1-Assumptions!$E$27) -> 1.690382 | I11: =Operating!F20*Assumptions!$E$29 -> 1.64142 | J11: =Operating!F20*Assumptions!$E$30 -> 1.753335 | K11: =Operating!F20*Assumptions!$E$33 -> 1.93986 | L11: =Operating!F20*(1-SUM(Assumptions!$E$29:$E$30)-Assumptions!$E$33) -> 2.126385 | M11: =Operating!G20*1 -> 9.84 | N11: =Operating!H20*1 -> 13.368 | O11: =Operating!I20*1 -> 17.3 | P11: =Operating!J20*1 -> 20.378 | Q11: =Operating!K20*1 -> 22.956 | R11: =Operating!L20*1 -> 25.534 | S11: =Operating!M20*1 -> 28.112 | T11: =Operating!N20*1 -> 30.69
C12: Adjusted operating expense | E12: =Sources!E23 -> 0.733 | F12: =Assumptions!$E$25 -> 0.78 | G12: =(Operating!E23-$E$12-$F$12)*Assumptions!$E$27 -> 0.8225 | H12: =(Operating!E23-$E$12-$F$12)*(1-Assumptions!$E$27) -> 0.9275 | I12: =Operating!F23*Assumptions!$E$29 -> 0.8184 | J12: =Operating!F23*Assumptions!$E$30 -> 0.8742 | K12: =Operating!F23*Assumptions!$E$33 -> 0.9672 | L12: =Operating!F23*(1-SUM(Assumptions!$E$29:$E$30)-Assumptions!$E$33) -> 1.0602 | M12: =Operating!G23*1 -> 4.28 | N12: =Operating!H23*1 -> 4.92 | O12: =Operating!I23*1 -> 6.3 | P12: =Operating!J23*1 -> 7.2 | Q12: =Operating!K23*1 -> 8 | R12: =Operating!L23*1 -> 8.8 | S12: =Operating!M23*1 -> 9.6 | T12: =Operating!N23*1 -> 10.4
C13: Compensation and other adjustments | E13: =E16-E12 -> 0.429 | F13: =Assumptions!$E$26 -> 0.4 | G13: =(Operating!E24-$E$13-$F$13)*Assumptions!$E$27 -> 0.31537 | H13: =(Operating!E24-$E$13-$F$13)*(1-Assumptions!$E$27) -> 0.35563 | I13: =Operating!F24*Assumptions!$E$29 -> 0.363 | J13: =Operating!F24*Assumptions!$E$30 -> 0.38775 | K13: =Operating!F24*Assumptions!$E$33 -> 0.429 | L13: =Operating!F24*(1-SUM(Assumptions!$E$29:$E$30)-Assumptions!$E$33) -> 0.47025 | M13: =Operating!G24*1 -> 1.8 | N13: =Operating!H24*1 -> 1.95 | O13: =Operating!I24*1 -> 2 | P13: =Operating!J24*1 -> 2.2 | Q13: =Operating!K24*1 -> 2.4 | R13: =Operating!L24*1 -> 2.6 | S13: =Operating!M24*1 -> 2.8 | T13: =Operating!N24*1 -> 3
C14: Research and development | E14: =Historical!H12 -> 0.838 | F14: =F16*Assumptions!$E$35 -> 0.885 | G14: =G16*Assumptions!$E$35 -> 0.8534025 | H14: =H16*Assumptions!$E$35 -> 0.9623475 | I14: =I16*Assumptions!$E$35 -> 0.88605 | J14: =J16*Assumptions!$E$35 -> 0.9464625 | K14: =K16*Assumptions!$E$35 -> 1.04715 | L14: =L16*Assumptions!$E$35 -> 1.1478375 | M14: =M16*Assumptions!$E$35 -> 4.56 | ... T14: =T16*Assumptions!$E$35 -> 10.05
C15: Other operating expenses | E15: =SUM(Historical!H13:H14) -> 0.324 | F15: =F16-F14 -> 0.295 | G15: =G16-G14 -> 0.2844675 | H15: =H16-H14 -> 0.3207825 | I15: =I16-I14 -> 0.29535 | J15: =J16-J14 -> 0.3154875 | K15: =K16-K14 -> 0.34905 | L15: =L16-L14 -> 0.3826125 | M15: =M16-M14 -> 1.52 | ... T15: =T16-T14 -> 3.35
C16: Total operating expense | E16: =Historical!H15 -> 1.162 | F16: =SUM(F12:F13) -> 1.18 | G16: =SUM(G12:G13) -> 1.13787 | H16: =SUM(H12:H13) -> 1.28313 | I16: =SUM(I12:I13) -> 1.1814 | J16: =SUM(J12:J13) -> 1.26195 | K16: =SUM(K12:K13) -> 1.3962 | L16: =SUM(L12:L13) -> 1.53045 | M16: =SUM(M12:M13) -> 6.08 | ... T16: =SUM(T12:T13) -> 13.4
C17: Operating income | E17: =Historical!H16 -> 0.091 | F17: =F11-F16 -> 0.1724 | G17: =G11-G16 -> 0.361148 | H17: =H11-H16 -> 0.407252 | I17: =I11-I16 -> 0.46002 | J17: =J11-J16 -> 0.491385 | K17: =K11-K16 -> 0.54366 | L17: =L11-L16 -> 0.595935 | M17: =M11-M16 -> 3.76 | ... T17: =T11-T16 -> 17.29
C18: Non-operating income | E18: =SUM(Historical!H17:H19) -> 0.162 | F18: =0 -> 0 | G18: =0 -> 0 | H18: =0 -> 0 | I18: =0 -> 0 | J18: =0 -> 0 | K18: =0 -> 0 | L18: =0 -> 0 | M18: =0 -> 0 | ... T18: =0 -> 0
C19: Income before tax | E19: =Historical!H20 -> 0.253 | F19: =SUM(F17:F18) -> 0.1724 | G19: =SUM(G17:G18) -> 0.361148 | H19: =SUM(H17:H18) -> 0.407252 | I19: =SUM(I17:I18) -> 0.46002 | J19: =SUM(J17:J18) -> 0.491385 | K19: =SUM(K17:K18) -> 0.54366 | L19: =SUM(L17:L18) -> 0.595935 | M19: =SUM(M17:M18) -> 3.76 | ... T19: =SUM(T17:T18) -> 17.29
C20: Tax expense / benefit | E20: =Historical!H21 -> -0.017 | F20: =F19*Assumptions!$E$36 -> 0.031032 | G20: =G19*Assumptions!$E$36 -> 0.06500664 | H20: =H19*Assumptions!$E$36 -> 0.07330536 | I20: =I19*Assumptions!$E$36 -> 0.0828036 | J20: =J19*Assumptions!$E$36 -> 0.0884493 | K20: =K19*Assumptions!$E$36 -> 0.0978588 | L20: =L19*Assumptions!$E$36 -> 0.1072683 | M20: =M19*Assumptions!$E$36 -> 0.6768 | ... T20: =T19*Assumptions!$E$36 -> 3.1122
C21: Net income | E21: =Historical!H22 -> 0.27 | F21: =F19-F20 -> 0.141368 | G21: =G19-G20 -> 0.29614136 | H21: =H19-H20 -> 0.33394664 | I21: =I19-I20 -> 0.3772164 | J21: =J19-J20 -> 0.4029357 | K21: =K19-K20 -> 0.4458012 | L21: =L19-L20 -> 0.4886667 | M21: =M19-M20 -> 3.0832 | ... T21: =T19-T20 -> 14.1778
C22: Diluted shares | E22: =Historical!H23 -> 1.078 | F22: =Assumptions!$E$15 -> 1.08 | G22: =Assumptions!$E$15 -> 1.08 | H22: =Assumptions!$E$15 -> 1.08 | I22: =Assumptions!$E$15 -> 1.08 | J22: =Assumptions!$E$15 -> 1.08 | K22: =Assumptions!$E$15 -> 1.08 | L22: =Assumptions!$E$15 -> 1.08 | M22: =Assumptions!$E$15 -> 1.08 | ... T22: =Assumptions!$E$15 -> 1.08
C23: EPS | E23: =E21/E22 -> 0.25046382 | F23: =F21/F22 -> 0.1308963 | G23: =G21/G22 -> 0.27420496 | H23: =H21/H22 -> 0.30920985 | I23: =I21/I22 -> 0.34927444 | J23: =J21/J22 -> 0.37308861 | K23: =K21/K22 -> 0.41277889 | L23: =L21/L22 -> 0.45246917 | ... T23: =T21/T22 -> 13.127593
C25: D&A | E25: =Historical!H28 -> 0.075 | F25: =F9*Assumptions!E75 -> 0.0552 | G25: =G9*Assumptions!E75 -> 0.0637508 | H25: =H9*Assumptions!E75 -> 0.0718892 | I25: =I9*Assumptions!F75 -> 0.0726 | J25: =J9*Assumptions!F75 -> 0.07755 | K25: =K9*Assumptions!F75 -> 0.0858 | L25: =L9*Assumptions!F75 -> 0.09405 | M25: =M9*Assumptions!G75 -> 0.48 | N25: =N9*Assumptions!H75 -> 0.72 | O25: =O9*Assumptions!I75 -> 1 | P25: =P9*Assumptions!J75 -> 1.204 | Q25: =Q9*Assumptions!K75 -> 1.368 | R25: =R9*Assumptions!L75 -> 1.532 | S25: =S9*Assumptions!M75 -> 1.696 | T25: =T9*Assumptions!N75 -> 1.86
C26: Non-cash SBC | E26: =Historical!H29 -> 0.343 | F26: =F13*Assumptions!E85 -> 0.31181818 | G26: =G13*Assumptions!E85 -> 0.24584525 | H26: =H13*Assumptions!E85 -> 0.27722975 | I26: =I13*Assumptions!F85 -> 0.282975 | J26: =J13*Assumptions!F85 -> 0.30226875 | K26: =K13*Assumptions!F85 -> 0.334425 | L26: =L13*Assumptions!F85 -> 0.36658125 | M26: =M13*Assumptions!G85 -> 1.4031818 | N26: =N13*Assumptions!H85 -> 1.5201136 | O26: =O13*Assumptions!I85 -> 1.5590909 | P26: =P13*Assumptions!J85 -> 1.715 | Q26: =Q13*Assumptions!K85 -> 1.8709091 | R26: =R13*Assumptions!L85 -> 2.0268182 | S26: =S13*Assumptions!M85 -> 2.1827273 | T26: =T13*Assumptions!N85 -> 2.3386364
C27: Cash capital spending | E27: =SUM(Historical!H30:H32) -> 0.237 | F27: =F9*Assumptions!E70 -> 0.1104 | G27: =G9*Assumptions!E70 -> 0.1275016 | H27: =H9*Assumptions!E70 -> 0.1437784 | I27: =I9*Assumptions!F70 -> 0.1452 | J27: =J9*Assumptions!F70 -> 0.1551 | K27: =K9*Assumptions!F70 -> 0.1716 | L27: =L9*Assumptions!F70 -> 0.1881 | M27: =M9*Assumptions!G70 -> 0.96 | N27: =N9*Assumptions!H70 -> 1.44 | O27: =O9*Assumptions!I70 -> 2 | P27: =P9*Assumptions!J70 -> 2.408 | Q27: =Q9*Assumptions!K70 -> 2.736 | R27: =R9*Assumptions!L70 -> 3.064 | S27: =S9*Assumptions!M70 -> 3.392 | T27: =T9*Assumptions!N70 -> 3.72
C28: Opening depreciable assets | E28: =SUM(Historical!E43,Historical!E45,Historical!E48) -> 1.071 | F28: =E29 -> 1.202 | G28: =F29 -> 1.2572 | H28: =G29 -> 1.3209508 | I28: =H29 -> 1.39284 | J28: =I29 -> 1.46544 | K28: =J29 -> 1.54299 | L28: =K29 -> 1.62879 | M28: =L29 -> 1.72284 | ... T28: =S29 -> 9.72284
C29: Closing depreciable assets | E29: =SUM(Historical!G43,Historical!G45,Historical!G48) -> 1.202 | F29: =SUM(F28,F27)-F25 -> 1.2572 | G29: =SUM(G28,G27)-G25 -> 1.3209508 | H29: =SUM(H28,H27)-H25 -> 1.39284 | I29: =SUM(I28,I27)-I25 -> 1.46544 | J29: =SUM(J28,J27)-J25 -> 1.54299 | K29: =SUM(K28,K27)-K25 -> 1.62879 | L29: =SUM(L28,L27)-L25 -> 1.72284 | M29: =SUM(M28,M27)-M25 -> 2.20284 | ... T29: =SUM(T28,T27)-T25 -> 11.58284
C30: Operating assets excluding cash | E30: =SUM(Historical!G40:G42,Historical!G50) -> 2.817 | F30: =F32*$E$30/$E$32 -> 3.1318912 | G30: =G32*$E$30/$E$32 -> 3.6170393 | H30: =H32*$E$30/$E$32 -> 4.0787891 | I30: =I32*$E$30/$E$32 -> 4.1191178 | J30: =J32*$E$30/$E$32 -> 4.3999668 | K30: =K32*$E$30/$E$32 -> 4.8680483 | L30: =L32*$E$30/$E$32 -> 5.3361299 | M30: =M32*$E$30/$E$32 -> 6.8084592 | ... T30: =T32*$E$30/$E$32 -> 26.382779
C31: Operating accruals and contract liabilities | E31: =SUM(Historical!G54,Historical!G56,Historical!G58:G59,Historical!G61) -> 1.824 | F31: =F32*$E$31/$E$32 -> 2.0278912 | G31: =G32*$E$31/$E$32 -> 2.3420233 | H31: =H32*$E$31/$E$32 -> 2.6410051 | I31: =I32*$E$31/$E$32 -> 2.6671178 | J31: =J32*$E$31/$E$32 -> 2.8489668 | K31: =K32*$E$31/$E$32 -> 3.1520483 | L31: =L32*$E$31/$E$32 -> 3.4551299 | M31: =M32*$E$31/$E$32 -> 4.4084592 | ... T31: =T32*$E$31/$E$32 -> 17.082779
C32: Net operating working capital | E32: =E30-E31 -> 0.993 | F32: =F9/F8*Assumptions!E80 -> 1.104 | G32: =G9/G8*Assumptions!E80 -> 1.275016 | H32: =H9/H8*Assumptions!E80 -> 1.437784 | I32: =I9/I8*Assumptions!F80 -> 1.452 | J32: =J9/J8*Assumptions!F80 -> 1.551 | K32: =K9/K8*Assumptions!F80 -> 1.716 | L32: =L9/L8*Assumptions!F80 -> 1.881 | M32: =M9/M8*Assumptions!G80 -> 2.4 | N32: =N9/N8*Assumptions!H80 -> 3.6 | O32: =O9/O8*Assumptions!I80 -> 5 | P32: =P9/P8*Assumptions!J80 -> 6.02 | Q32: =Q9/Q8*Assumptions!K80 -> 6.84 | R32: =R9/R8*Assumptions!L80 -> 7.66 | S32: =S9/S8*Assumptions!M80 -> 8.48 | T32: =T9/T8*Assumptions!N80 -> 9.3
C33: Change in operating assets | F33: =F30-E30 -> 0.31489124 | G33: =G30-F30 -> 0.48514811 | H33: =H30-G30 -> 0.4617497 | I33: =I30-H30 -> 0.040328773 | J33: =J30-I30 -> 0.28084894 | K33: =K30-J30 -> 0.46808157 | L33: =L30-K30 -> 0.46808157 | M33: =M30-L30 -> 1.4723293 | ... T33: =T30-S30 -> 2.3262236
C34: Change in operating liabilities | F34: =F31-E31 -> 0.20389124 | G34: =G31-F31 -> 0.31413211 | H34: =H31-G31 -> 0.2989817 | I34: =I31-H31 -> 0.026112773 | J34: =J31-I31 -> 0.18184894 | K34: =K31-J31 -> 0.30308157 | L34: =L31-K31 -> 0.30308157 | M34: =M31-L31 -> 0.95332931 | ... T34: =T31-S31 -> 1.5062236
C35: Change in net working capital | F35: =F32-E32 -> 0.111 | G35: =G32-F32 -> 0.171016 | H35: =H32-G32 -> 0.162768 | I35: =I32-H32 -> 0.014216 | J35: =J32-I32 -> 0.099 | K35: =K32-J32 -> 0.165 | L35: =L32-K32 -> 0.165 | M35: =M32-L32 -> 0.519 | ... T35: =T32-S32 -> 0.82
C37: Cash from operations | E37: =Historical!G91 -> 0.902 | F37: =SUM(F21,F25:F26)-F33+F34 -> 0.39738618 | G37: =SUM(G21,G25:G26)-G33+G34 -> 0.43472141 | H37: =SUM(H21,H25:H26)-H33+H34 -> 0.52029759 | I37: =SUM(I21,I25:I26)-I33+I34 -> 0.7185754 | J37: =SUM(J21,J25:J26)-J33+J34 -> 0.68375445 | K37: =SUM(K21,K25:K26)-K33+K34 -> 0.7010262 | L37: =SUM(L21,L25:L26)-L33+L34 -> 0.78429795 | M37: =SUM(M21,M25:M26)-M33+M34 -> 4.4473818 | ... T37: =SUM(T21,T25:T26)-T33+T34 -> 17.556436
C38: Capital spending cash flow | E38: =-E27 -> -0.237 | F38: =-F27 -> -0.1104 | G38: =-G27 -> -0.1275016 | H38: =-H27 -> -0.1437784 | I38: =-I27 -> -0.1452 | J38: =-J27 -> -0.1551 | K38: =-K27 -> -0.1716 | L38: =-L27 -> -0.1881 | ... T38: =-T27 -> -3.72
C39: Acquisitions | E39: =0 -> 0 | F39: =-Assumptions!$E$34 -> -0.265 | G39: =0 -> 0 | H39: =0 -> 0 | I39: =0 -> 0 | J39: =0 -> 0 | K39: =0 -> 0 | L39: =0 -> 0 | M39: =0 -> 0 | N39: =0 -> 0 | ... T39: =0 -> 0
C40: Other investment cash flows | E40: =Historical!G100-E38 -> -0.03 | F40: =0 -> 0 | G40: =0 -> 0 | H40: =0 -> 0 | I40: =0 -> 0 | J40: =0 -> 0 | K40: =0 -> 0 | L40: =0 -> 0 | M40: =0 -> 0 | ... T40: =0 -> 0
C41: Cash from investing | E41: =Historical!G100 -> -0.267 | F41: =SUM(F38:F40) -> -0.3754 | G41: =SUM(G38:G40) -> -0.1275016 | H41: =SUM(H38:H40) -> -0.1437784 | I41: =SUM(I38:I40) -> -0.1452 | J41: =SUM(J38:J40) -> -0.1551 | K41: =SUM(K38:K40) -> -0.1716 | L41: =SUM(L38:L40) -> -0.1881 | M41: =SUM(M38:M40) -> -0.96 | ... T41: =SUM(T38:T40) -> -3.72
C42: Offset SBC repurchases / tax withholding | E42: =Historical!G104 -> -0.278 | F42: =-F26*Assumptions!$E$28 -> -0.31181818 | G42: =-G26*Assumptions!$E$28 -> -0.24584525 | H42: =-H26*Assumptions!$E$28 -> -0.27722975 | I42: =-I26*Assumptions!$E$28 -> -0.282975 | J42: =-J26*Assumptions!$E$28 -> -0.30226875 | K42: =-K26*Assumptions!$E$28 -> -0.334425 | L42: =-L26*Assumptions!$E$28 -> -0.36658125 | M42: =-M26*Assumptions!$E$28 -> -1.4031818 | ... T42: =-T26*Assumptions!$E$28 -> -2.3386364
C43: Other financing cash flow | E43: =Historical!G105-E42 -> -0.048 | F43: =-Assumptions!$E$21*Assumptions!$E$15*F8 -> 0 | G43: =-Assumptions!$E$21*Assumptions!$E$15*G8 -> 0 | H43: =-Assumptions!$E$21*Assumptions!$E$15*H8 -> 0 | I43: =-Assumptions!$E$21*Assumptions!$E$15*I8 -> 0 | J43: =-Assumptions!$E$21*Assumptions!$E$15*J8 -> 0 | K43: =-Assumptions!$E$21*Assumptions!$E$15*K8 -> 0 | L43: =-Assumptions!$E$21*Assumptions!$E$15*L8 -> 0 | M43: =-Assumptions!$E$21*Assumptions!$E$15*M8 -> 0 | ... T43: =-Assumptions!$E$21*Assumptions!$E$15*T8 -> 0
C44: Cash from financing | E44: =Historical!G105 -> -0.326 | F44: =SUM(F42:F43) -> -0.31181818 | G44: =SUM(G42:G43) -> -0.24584525 | H44: =SUM(H42:H43) -> -0.27722975 | I44: =SUM(I42:I43) -> -0.282975 | J44: =SUM(J42:J43) -> -0.30226875 | K44: =SUM(K42:K43) -> -0.334425 | L44: =SUM(L42:L43) -> -0.36658125 | M44: =SUM(M42:M43) -> -1.4031818 | ... T44: =SUM(T42:T43) -> -2.3386364
C45: FX and other cash effects | E45: =Historical!G106 -> -0.002 | F45: =0 -> 0 | G45: =0 -> 0 | H45: =0 -> 0 | I45: =0 -> 0 | J45: =0 -> 0 | K45: =0 -> 0 | L45: =0 -> 0 | M45: =0 -> 0 | ... T45: =0 -> 0
...

Sheet DCF
C2: DCF
C3: USD billions, except shares in billions and per-share amounts. FY ends 31 March.
C4: Selected case | E4: =CHOOSE(Assumptions!$E$5,"Bear","Base","Bull") -> Base
C5: WACC | E5: =Assumptions!E90 -> 0.115
C6: Terminal growth | E6: =Assumptions!E16 -> 0.03
C8: Elapsed years from June 30 | E8: =(Assumptions!E9-Assumptions!E11)/365 -> 0.29589041
C9: Target years from June 30 | E9: =E8+(Assumptions!E10-Assumptions!E9)/365 -> 1.2958904
C10: Opening cash plus short investments | E10: =SUM(Statements!E50:E51) -> 3.888
C11: Known July acquisition | E11: =Assumptions!E34 -> 0.265
C12: Net financial debt | E12: =Assumptions!E37 -> 0
C13: Equity investments recovered | E13: =Statements!E55*Assumptions!E18 -> 0.2945
C14: Diluted shares | E14: =Assumptions!E15 -> 1.08
F17: Q2 FY27E | G17: Q3 FY27E | H17: Q4 FY27E | I17: Q1 FY28E | J17: Q2 FY28E | K17: Q3 FY28E | L17: Q4 FY28E | M17: FY2029E | N17: FY2030E | O17: FY2031E | P17: FY2032E | Q17: FY2033E | R17: FY2034E | S17: FY2035E | T17: FY2036E
C18: Period duration | F18: =Statements!F8 -> 0.25 | G18: =Statements!G8 -> 0.25 | H18: =Statements!H8 -> 0.25 | I18: =Statements!I8 -> 0.25 | J18: =Statements!J8 -> 0.25 | K18: =Statements!K8 -> 0.25 | L18: =Statements!L8 -> 0.25 | M18: =Statements!M8 -> 1 | ... T18: =Statements!T8 -> 1
C19: Period start in years | F19: =0 -> 0 | G19: =F20 -> 0.25 | H19: =G20 -> 0.5 | I19: =H20 -> 0.75 | J19: =I20 -> 1 | K19: =J20 -> 1.25 | L19: =K20 -> 1.5 | M19: =L20 -> 1.75 | N19: =M20 -> 2.75 | ... T19: =S20 -> 8.75
C20: Period end in years | F20: =SUM(F18:F19) -> 0.25 | G20: =SUM(G18:G19) -> 0.5 | H20: =SUM(H18:H19) -> 0.75 | I20: =SUM(I18:I19) -> 1 | J20: =SUM(J18:J19) -> 1.25 | K20: =SUM(K18:K19) -> 1.5 | L20: =SUM(L18:L19) -> 1.75 | M20: =SUM(M18:M19) -> 2.75 | ... T20: =SUM(T18:T19) -> 9.75
C21: Economic FCFF | F21: =Statements!F74 -> -0.024832 | G21: =Statements!G74 -> 0.06137456 | H21: =Statements!H74 -> 0.09928944 | I21: =Statements!I74 -> 0.2904004 | J21: =Statements!J74 -> 0.2263857 | K21: =Statements!K74 -> 0.1950012 | L21: =Statements!L74 -> 0.2296167 | M21: =Statements!M74 -> 2.0842 | ... T21: =Statements!T74 -> 11.4978
C22: Financing difference versus economic FCFF | F22: =Statements!F26+Statements!F42+Statements!F43 -> 0 | G22: =Statements!G26+Statements!G42+Statements!G43 -> 0 | H22: =Statements!H26+Statements!H42+Statements!H43 -> 0 | I22: =Statements!I26+Statements!I42+Statements!I43 -> 0 | J22: =Statements!J26+Statements!J42+Statements!J43 -> 0 | K22: =Statements!K26+Statements!K42+Statements!K43 -> 0 | L22: =Statements!L26+Statements!L42+Statements!L43 -> 0 | M22: =Statements!M26+Statements!M42+Statements!M43 -> 0 | ... T22: =Statements!T26+Statements!T42+Statements!T43 -> 0
C23: Net economic cash accrual | F23: =SUM(F21:F22) -> -0.024832 | G23: =SUM(G21:G22) -> 0.06137456 | H23: =SUM(H21:H22) -> 0.09928944 | I23: =SUM(I21:I22) -> 0.2904004 | J23: =SUM(J21:J22) -> 0.2263857 | K23: =SUM(K21:K22) -> 0.1950012 | L23: =SUM(L21:L22) -> 0.2296167 | M23: =SUM(M21:M22) -> 2.0842 | ... T23: =SUM(T21:T22) -> 11.4978
C24: Fraction elapsed at reference date | F24: =MAX(0,MIN(1,($E$8-F19)/F18)) -> 1 | G24: =MAX(0,MIN(1,($E$8-G19)/G18)) -> 0.18356164 | H24: =MAX(0,MIN(1,($E$8-H19)/H18)) -> 0 | I24: =MAX(0,MIN(1,($E$8-I19)/I18)) -> 0 | J24: =MAX(0,MIN(1,($E$8-J19)/J18)) -> 0 | K24: =MAX(0,MIN(1,($E$8-K19)/K18)) -> 0 | L24: =MAX(0,MIN(1,($E$8-L19)/L18)) -> 0 | M24: =MAX(0,MIN(1,($E$8-M19)/M18)) -> 0 | ... T24: =MAX(0,MIN(1,($E$8-T19)/T18)) -> 0
C25: Fraction elapsed at target date | F25: =MAX(0,MIN(1,($E$9-F19)/F18)) -> 1 | G25: =MAX(0,MIN(1,($E$9-G19)/G18)) -> 1 | H25: =MAX(0,MIN(1,($E$9-H19)/H18)) -> 1 | I25: =MAX(0,MIN(1,($E$9-I19)/I18)) -> 1 | J25: =MAX(0,MIN(1,($E$9-J19)/J18)) -> 1 | K25: =MAX(0,MIN(1,($E$9-K19)/K18)) -> 0.18356164 | L25: =MAX(0,MIN(1,($E$9-L19)/L18)) -> 0 | M25: =MAX(0,MIN(1,($E$9-M19)/M18)) -> 0 | ... T25: =MAX(0,MIN(1,($E$9-T19)/T18)) -> 0
C26: PV factor at reference date | F26: =1/(1+$E$5)^(F20-$E$8) -> 1.0050079 | G26: =1/(1+$E$5)^(G20-$E$8) -> 0.97802678 | H26: =1/(1+$E$5)^(H20-$E$8) -> 0.95177004 | I26: =1/(1+$E$5)^(I20-$E$8) -> 0.9262182 | J26: =1/(1+$E$5)^(J20-$E$8) -> 0.90135235 | K26: =1/(1+$E$5)^(K20-$E$8) -> 0.87715406 | L26: =1/(1+$E$5)^(L20-$E$8) -> 0.85360542 | M26: =1/(1+$E$5)^(M20-$E$8) -> 0.7655654 | ... T26: =1/(1+$E$5)^(T20-$E$8) -> 0.35732074
C27: PV factor at target date | F27: =1/(1+$E$5)^(F20-$E$9) -> 1.1205838 | G27: =1/(1+$E$5)^(G20-$E$9) -> 1.0904999 | H27: =1/(1+$E$5)^(H20-$E$9) -> 1.0612236 | I27: =1/(1+$E$5)^(I20-$E$9) -> 1.0327333 | J27: =1/(1+$E$5)^(J20-$E$9) -> 1.0050079 | K27: =1/(1+$E$5)^(K20-$E$9) -> 0.97802678 | L27: =1/(1+$E$5)^(L20-$E$9) -> 0.95177004 | M27: =1/(1+$E$5)^(M20-$E$9) -> 0.85360542 | ... T27: =1/(1+$E$5)^(T20-$E$9) -> 0.39841262
C28: PV of remaining FCFF today | F28: =F21*(1-F24)*F26 -> 0 | G28: =G21*(1-G24)*G26 -> 0.049007499 | H28: =H21*(1-H24)*H26 -> 0.094500714 | I28: =I21*(1-I24)*I26 -> 0.26897414 | J28: =J21*(1-J24)*J26 -> 0.20405328 | K28: =K21*(1-K24)*K26 -> 0.17104609 | L28: =L21*(1-L24)*L26 -> 0.19600206 | M28: =M21*(1-M24)*M26 -> 1.5955914 | ... T28: =T21*(1-T24)*T26 -> 4.1084024
C29: PV of remaining FCFF at target | F29: =F21*(1-F25)*F27 -> 0 | G29: =G21*(1-G25)*G27 -> 0 | H29: =H21*(1-H25)*H27 -> 0 | I29: =I21*(1-I25)*I27 -> 0 | J29: =J21*(1-J25)*J27 -> 0 | K29: =K21*(1-K25)*K27 -> 0.15570818 | L29: =L21*(1-L25)*L27 -> 0.2185423 | M29: =M21*(1-M25)*M27 -> 1.7790844 | ... T29: =T21*(1-T25)*T27 -> 4.5808687
C30: Accrued cash through reference date | F30: =F23*F24 -> -0.024832 | G30: =G23*G24 -> 0.011266015 | H30: =H23*H24 -> 0 | I30: =I23*I24 -> 0 | J30: =J23*J24 -> 0 | K30: =K23*K24 -> 0 | L30: =L23*L24 -> 0 | M30: =M23*M24 -> 0 | ... T30: =T23*T24 -> 0
C31: Accrued cash through target date | F31: =F23*F25 -> -0.024832 | G31: =G23*G25 -> 0.06137456 | H31: =H23*H25 -> 0.09928944 | I31: =I23*I25 -> 0.2904004 | J31: =J23*J25 -> 0.2263857 | K31: =K23*K25 -> 0.035794741 | L31: =L23*L25 -> 0 | M31: =M23*M25 -> 0 | ... T31: =T23*T25 -> 0
C32: Base FCFF slope to proportional revenue | F32: =F21-Statements!$E$32 -> -1.017832 | G32: =G21 -> 0.06137456 | H32: =H21 -> 0.09928944 | I32: =I21 -> 0.2904004 | J32: =J21 -> 0.2263857 | K32: =K21 -> 0.1950012 | L32: =L21 -> 0.2296167 | M32: =M21 -> 2.0842 | N32: =N21 -> 3.40836 | ... T32: =T21 -> 11.4978
C33: Revenue slope of current equity value | F33: =F32*(F24+(1-F24)*F26) -> -1.017832 | G33: =G32*(G24+(1-G24)*G26) -> 0.060273514 | H33: =H32*(H24+(1-H24)*H26) -> 0.094500714 | I33: =I32*(I24+(1-I24)*I26) -> 0.26897414 | J33: =J32*(J24+(1-J24)*J26) -> 0.20405328 | K33: =K32*(K24+(1-K24)*K26) -> 0.17104609 | L33: =L32*(L24+(1-L24)*L26) -> 0.19600206 | M33: =M32*(M24+(1-M24)*M26) -> 1.5955914 | ... T33: =T32*(T24+(1-T24)*T26) -> 4.1084024
C36: Final-year NOPAT | E36: =Statements!T17*(1-Assumptions!E36) -> 14.1778
C37: Terminal reinvestment rate | E37: =E6/Assumptions!E17 -> 0.1
C38: Terminal FCFF | E38: =E36*(1+E6)*(1-E37) -> 13.142821
C39: Terminal enterprise value | E39: =E38/(E5-E6) -> 154.62142
C41: PV explicit FCFF today | E41: =SUM(F28:T28) -> 28.088138
C42: PV terminal value today | E42: =E39/(1+E5)^(T20-E8) -> 55.24944
C43: Current enterprise value | E43: =SUM(E41:E42) -> 83.337577
C44: Cash at reference date | E44: =E10-E11+SUM(F30:T30) -> 3.609434
C45: Current equity value | E45: =SUM(E43:E44,E13)-E12 -> 87.241511
C46: Current DCF per share | E46: =E45/E14 -> 80.779177
C48: PV explicit FCFF at target | E48: =SUM(F29:T29) -> 30.595828
...

Sheet Comps
C2: Comps
C3: USD billions, except shares in billions and per-share amounts. FY ends 31 March.
C4: Selected case | E4: =CHOOSE(Assumptions!$E$5,"Bear","Base","Bull") -> Base
C7: Company | D7: Ticker | E7: Price ($) | F7: Forward EPS | G7: Fiscal end | H7: P/E | I7: Business comparison
C8: =Sources!C31 -> Arm | D8: =Sources!D31 -> ARM | E8: =Sources!E31 -> 227.8 | F8: =Sources!F31 -> 3.06 | G8: =Sources!G31 -> 46843 | H8: =E8/F8 -> 74.444444 | I8: IP and own CPU
C9: =Sources!C32 -> AMD | D9: =Sources!D32 -> AMD | E9: =Sources!E32 -> 528.75 | F9: =Sources!F32 -> 15.76 | G9: =Sources!G32 -> 46752 | H9: =E9/F9 -> 33.550127 | I9: Server CPU designer
C10: =Sources!C33 -> Cadence | D10: =Sources!D33 -> CDNS | E10: =Sources!E33 -> 319.51 | F10: =Sources!F33 -> 9.57 | G10: =Sources!G33 -> 46752 | H10: =E10/F10 -> 33.386625 | I10: EDA and semiconductor IP
C11: =Sources!C34 -> Synopsys | D11: =Sources!D34 -> SNPS | E11: =Sources!E34 -> 454.63 | F11: =Sources!F34 -> 18.67 | G11: =Sources!G34 -> 46691 | H11: =E11/F11 -> 24.35083 | I11: EDA and semiconductor IP
C15: Street FY28 adjusted EPS | E15: =Sources!E18 -> 3.06
C16: Street EPS multiple | E16: =Assumptions!E31 -> 40
C17: Street-based price | E17: =E15*E16 -> 122.4
C19: Own FY28 operating EPS proxy | E19: =Operating!F32 -> 2.8403889
C20: Own EPS multiple | E20: =Assumptions!E32 -> 45
C21: Own EPS-based price | E21: =E19*E20 -> 127.8175
C23: Rounded midpoint target | E23: =ROUND(AVERAGE(E17,E21),0) -> 125
C24: Gross price downside | E24: =1-E23/Assumptions!E8 -> 0.45127305
C26: AMD and Cadence average P/E | E26: =AVERAGE(H9:H10) -> 33.468376
C27: Premium of street multiple | E27: =E16/E26-1 -> 0.19515808
C28: Premium of own multiple | E28: =E20/E26-1 -> 0.34455284
C30: Management FY31 EPS illustration | E30: 9
C31: Illustrative FY31 P/E | E31: 40
C32: Years from target to FY31 end | E32: =(DATE(2031,3,31)-Assumptions!E10)/365 -> 3.4575342
C33: Discounted FY31 earnings valuation | E33: =E30*E31/(1+DCF!E5)^E32 -> 247.08594
C36: Fiscal periods are not calendarized. Adjusted earnings definitions differ; peers are a valuation cross-check, not direct substitutes.
C37: 40x-45x retains a premium for IP economics and growth. It is a judgment, not a market-implied or guaranteed exit multiple.
C38: The rounded target is not averaged with DCF. The own operating EPS proxy excludes non-operating gains and interest income.
C39: The $9 management illustration challenges the short. The company ambition is above $9; this row uses $9 for a transparent example.

Sheet Short return
C2: Short return
C3: USD billions, except shares in billions and per-share amounts. FY ends 31 March.
C4: Selected case | E4: =CHOOSE(Assumptions!$E$5,"Bear","Base","Bull") -> Base
C8: Reference price | E8: =Assumptions!E8 -> 227.8
C9: Exit target | E9: =Comps!E23 -> 125
C10: Annual borrow rate | E10: =Assumptions!E19 -> 0.06
C11: Holding years | E11: =(Assumptions!E10-Assumptions!E9)/365 -> 1
C12: Dividends paid per share | E12: =Assumptions!E21*E11 -> 0
C13: Gross profit per share | E13: =E8-E9-E12 -> 102.8
C14: Borrow cost per share | E14: =E8*E10*E11 -> 13.668
C15: Net profit per share | E15: =E13-E14 -> 89.132
C16: Return on initial notional | E16: =E15/E8 -> 0.39127305
C17: Break-even exit price | E17: =E8-E14-E12 -> 214.132
C18: Initial collateral | E18: =E8*Assumptions!E20 -> 113.9
C19: Simple return on collateral | E19: =E15/E18 -> 0.78254609
C20: Collateral XIRR | E20: =XIRR(F25:F29,E25:E29) -> 0.75259844
E24: Date | F24: Cash flow ($)
E25: =Assumptions!E9 -> 46311 | F25: =-E18 -> -113.9
E26: =EDATE($E$25,3) -> 46403 | F26: =-$E$14/4 -> -3.417
E27: =EDATE($E$25,6) -> 46493 | F27: =-$E$14/4 -> -3.417
E28: =EDATE($E$25,9) -> 46584 | F28: =-$E$14/4 -> -3.417
E29: =Assumptions!E10 -> 46676 | F29: =E18+E13-E14/4 -> 213.283
C32: Net short return by exit price and annual borrow fee
F34: 0.03 | G34: 0.06 | H34: 0.12 | I34: 0.2
C35: $125 target | E35: =E9 -> 125 | F35: =($E$8-$E35-$E$12)/$E$8-F$34*$E$11 -> 0.42127305 | G35: =($E$8-$E35-$E$12)/$E$8-G$34*$E$11 -> 0.39127305 | H35: =($E$8-$E35-$E$12)/$E$8-H$34*$E$11 -> 0.33127305 | I35: =($E$8-$E35-$E$12)/$E$8-I$34*$E$11 -> 0.25127305
C36: No price change | E36: =E8 -> 227.8 | F36: =($E$8-$E36-$E$12)/$E$8-F$34*$E$11 -> -0.03 | G36: =($E$8-$E36-$E$12)/$E$8-G$34*$E$11 -> -0.06 | H36: =($E$8-$E36-$E$12)/$E$8-H$34*$E$11 -> -0.12 | I36: =($E$8-$E36-$E$12)/$E$8-I$34*$E$11 -> -0.2
C37: Active-case DCF | E37: =DCF!E53 -> 89.634135 | F37: =($E$8-$E37-$E$12)/$E$8-F$34*$E$11 -> 0.57652267 | G37: =($E$8-$E37-$E$12)/$E$8-G$34*$E$11 -> 0.54652267 | H37: =($E$8-$E37-$E$12)/$E$8-H$34*$E$11 -> 0.48652267 | I37: =($E$8-$E37-$E$12)/$E$8-I$34*$E$11 -> 0.40652267
C38: Bull report reference | E38: 346.88816 | F38: =($E$8-$E38-$E$12)/$E$8-F$34*$E$11 -> -0.55277509 | G38: =($E$8-$E38-$E$12)/$E$8-G$34*$E$11 -> -0.58277509 | H38: =($E$8-$E38-$E$12)/$E$8-H$34*$E$11 -> -0.64277509 | I38: =($E$8-$E38-$E$12)/$E$8-I$34*$E$11 -> -0.72277509
C41: The bull report reference is fixed from the report, not a live second forecast. Select case 3 to see the current bull DCF.
C42: Collateral XIRR assumes 50% initial margin, restricted sale proceeds, quarterly fees and no margin calls. It is not a quoted broker return.
C43: Borrow can be recalled and repriced. Commissions, taxes, interest and rebates are excluded. Short losses are unbounded.
C44: An actual flat share price loses the borrow cost. Positive base-case value does not remove timing and execution risk.

Sheet Historical
C2: Historical
C3: USD billions, except shares in billions and per-share amounts. FY ends 31 March.
C4: Selected case | E4: =CHOOSE(Assumptions!$E$5,"Bear","Base","Bull") -> Base
E7: FY2024A | F7: FY2025A | G7: FY2026A | H7: Q1 FY2027A | J7: Reported source
C9: Revenue | E9: 3.233 | F9: 4.007 | G9: 4.92 | H9: 1.289 | J9: S2 annual statements; S3 quarterly statements. All amounts scaled from USD millions.
C10: Cost of sales | E10: 0.154 | F10: 0.121 | G10: 0.121 | H10: 0.036
C11: Gross profit | E11: 3.079 | F11: 3.886 | G11: 4.799 | H11: 1.253
C12: Research and development | E12: 1.979 | F12: 2.071 | G12: 2.776 | H12: 0.838
C13: Selling general administrative | E13: 0.983 | F13: 0.984 | G13: 1.115 | H13: 0.317
C14: Other operating expense | E14: 0.006 | F14: 0 | G14: 0.008 | H14: 0.007
C15: Operating expenses | E15: 2.968 | F15: 3.055 | G15: 3.899 | H15: 1.162
C16: Operating income | E16: 0.111 | F16: 0.831 | G16: 0.9 | H16: 0.091
C17: Equity investment income / loss | E17: -0.02 | F17: -0.237 | G17: 0.014 | H17: 0.128
C18: Net interest income | E18: 0.11 | F18: 0.116 | G18: 0.111 | H18: 0.031
C19: Other non-operating income | E19: 0.011 | F19: 0.01 | G19: 0.132 | H19: 0.003
C20: Pre-tax income | E20: 0.212 | F20: 0.72 | G20: 1.157 | H20: 0.253
C21: Income tax expense / benefit | E21: -0.094 | F21: -0.072 | G21: 0.253 | H21: -0.017
... C32: Intangible obligation payments | E32: 0.04 | F32: 0.059 | G32: 0.067 | H32: 0.029
C35: Reported balance sheets
E36: 31-Mar-2026 | G36: 30-Jun-2026
C38: Cash and cash equivalents | E38: 2.751 | G38: 3.058 | J38: S3, balance sheets pages 6-7. Book values are not fair-value estimates.
C39: Short-term investments | E39: 0.85 | G39: 0.83
C40: Accounts receivable | E40: 1.3 | G40: 1.119
C41: Current contract assets | E41: 0.977 | G41: 0.881
C42: Prepaid and other current assets | E42: 0.358 | G42: 0.451
C43: Property and equipment | E43: 0.772 | G43: 0.923
C44: Operating lease ROU assets | E44: 0.379 | G44: 0.406
C45: Finance lease ROU assets | E45: 0.069 | G45: 0.062
C46: Equity investments | E46: 0.387 | G46: 0.589
C47: Goodwill | E47: 1.623 | G47: 1.623
C48: Intangible assets | E48: 0.23 | G48: 0.217
C49: Deferred tax assets | E49: 0.375 | G49: 0.425
C50: Non-current contract assets | E50: 0.32 | G50: 0.366
... C70: Total shareholders equity | E70: 8.286 | G70: 8.63
C74: Q1 FY2027 cash-flow reconciliation
C76: Net income | G76: 0.27 | J76: S3 cash-flow statement page 9. Historical withholding is not presented as an announced repurchase.
C77: D&A | G77: 0.075
C78: Deferred taxes | G78: -0.066
C79: Investment gains adjustment | G79: -0.128
C80: Non-cash SBC | G80: 0.343
...

Sheet Sources
C2: Sources
C3: USD billions, except shares in billions and per-share amounts. FY ends 31 March.
C4: Selected case | E4: =CHOOSE(Assumptions!$E$5,"Bear","Base","Bull") -> Base
C8: ARM reference close | E8: 227.8 | G8: S6, 16 October 2026
C9: Reference date | E9: 46311 | G9: Research valuation date
C10: Target date | E10: 46676 | G10: One-year horizon
C11: Opening financial date | E11: 46203 | G11: S3
C12: Eligibility date close | E12: 293.67 | G12: S6, 29 September 2026
C13: Reported ordinary shares | E13: 1.068 | G13: S3, June 2026; proxy for eligibility cap
C15: Q2 FY27 revenue guide midpoint | E15: 1.38 | G15: S4
C16: Q2 adjusted OpEx guide | E16: 0.78 | G16: S4
C17: July acquisition cash payment | E17: 0.265 | G17: S3, Note 16
C18: FY28 consensus adjusted EPS | E18: 3.06 | G18: S7
C19: FY28 consensus revenue | E19: 8.25 | G19: S7
C20: FY27 consensus revenue | E20: 6.06 | G20: S7
... C26: Reported group operating-profit gap | E26: 0.44 | G26: S4, GAAP reconciliation
C29: Comparable observations
C30: Company | D30: Ticker | E30: Close ($) | F30: Forward EPS ($) | G30: Fiscal end | H30: Source
C31: Arm | D31: ARM | E31: 227.8 | F31: 3.06 | G31: 46843 | H31: S7
C32: AMD | D32: AMD | E32: 528.75 | F32: 15.76 | G32: 46752 | H32: S11
C33: Cadence | D33: CDNS | E33: 319.51 | F33: 9.57 | G33: 46752 | H33: S12
C34: Synopsys | D34: SNPS | E34: 454.63 | F34: 18.67 | G34: 46691 | H34: S13
C37: Public sources and assumptions
C39: S1 Competition guidelines
C40: https://nanyangcapitalspc.com/guidelines
C41: Eligibility at Sep 29; horizon up to one year; report, appendix and 3FS Excel; team-owned analysis.
C43: S2 Arm FY2026 Form 20-F
C44: https://www.sec.gov/Archives/edgar/data/1973239/000197323926000097/arm-20260331.htm
C45: Income statements p127, cash flows p132-133, revenue note. Filed 26 May 2026.
C47: S3 Arm July 2026 Form 6-K
C48: https://investors.arm.com/static-files/69c13c55-810b-4de8-93b6-7cea395659ea
C49: June statements pp4-9; Note 2 balance detail; Note 16 DreamBig acquisition.
C51: S4 Q1 FY2027 shareholder letter
C52: https://investors.arm.com/static-files/d8db20bd-7b96-486a-b99b-23315627d1ec
... C95: Accounting forecast simplifies lease and tax book balances. No forecast fair-value gains, acquisitions after DreamBig or FX gains.

Sheet Checks
C2: Checks
C3: USD billions, except shares in billions and per-share amounts. FY ends 31 March.
C4: Selected case | E4: =CHOOSE(Assumptions!$E$5,"Bear","Base","Bull") -> Base
C9: Opening asset reconciliation | E9: =SUM(Historical!G38:G51)-Historical!G52 -> 0
C10: Opening liability reconciliation | E10: =SUM(Historical!G54:G63)-Historical!G64 -> 0
C11: Opening equity reconciliation | E11: =SUM(Historical!G66:G69)-Historical!G70 -> 0
C12: Opening balance sheet | E12: =Historical!G52-Historical!G64-Historical!G70 -> 0
C13: Reported Q1 CFO detail | E13: =SUM(Historical!G76:G90)-Historical!G91 -> 0
C14: Reported Q1 investing detail | E14: =SUM(Historical!G93:G99)-Historical!G100 -> 0
C15: Reported Q1 financing detail | E15: =SUM(Historical!G102:G104)-Historical!G105 -> 0
C16: Reported Q1 cash increase | E16: =SUM(Historical!G91,Historical!G100,Historical!G105:G106)-Historical!G107 -> 0
C17: Reported Q1 ending cash | E17: =SUM(Historical!G108,Historical!G107)-Historical!G109 -> 0
C18: FY27 revenue bridge | E18: =SUM(Statements!E9:H9)-Operating!E13 -> 0
C19: FY27 operating profit bridge | E19: =SUM(Statements!E17:H17)-Operating!E26 -> 0
C20: FY28 revenue bridge | E20: =SUM(Statements!I9:L9)-Operating!F13 -> 0
C21: FY28 operating profit bridge | E21: =SUM(Statements!I17:L17)-Operating!F26 -> 0
C22: DCF table base point | E22: =IF(Assumptions!E5=2,DCF!G73-DCF!E53,0) -> 0
C23: DCF cash and statements at target | E23: =DCF!E51-(Statements!J48+Statements!E51+(Statements!K48-Statements!J48)*DCF!K25) -> 0
C24: Repurchase fraction deviation | E24: =Assumptions!E28-1 -> 0
F28: Q2 FY27E | G28: Q3 FY27E | H28: Q4 FY27E | I28: Q1 FY28E | J28: Q2 FY28E | K28: Q3 FY28E | L28: Q4 FY28E | M28: FY2029E | N28: FY2030E | O28: FY2031E | P28: FY2032E | Q28: FY2033E | R28: FY2034E | S28: FY2035E | T28: FY2036E
C29: Balance sheet difference | F29: =Statements!F76 -> 0 | G29: =Statements!G76 -> 0 | H29: =Statements!H76 -> 0 | I29: =Statements!I76 -> 0 | J29: =Statements!J76 -> 0 | K29: =Statements!K76 -> 0 | L29: =Statements!L76 -> 0 | M29: =Statements!M76 -> 0 | ... T29: =Statements!T76 -> 0
C30: Economic cash flow reconciliation | F30: =Statements!F77 -> 2.220446e-16 | G30: =Statements!G77 -> -1.6653345e-16 | H30: =Statements!H77 -> 3.8857806e-16 | I30: =Statements!I77 -> 0 | J30: =Statements!J77 -> 0 | K30: =Statements!K77 -> -3.8857806e-16 | L30: =Statements!L77 -> 4.9960036e-16 | M30: =Statements!M77 -> 0 | ... T30: =Statements!T77 -> 0
C31: Depreciable asset roll-forward | F31: =Statements!F29-Statements!F28-Statements!F27+Statements!F25 -> 1.3877788e-16 | G31: =Statements!G29-Statements!G28-Statements!G27+Statements!G25 -> 0 | H31: =Statements!H29-Statements!H28-Statements!H27+Statements!H25 -> 0 | I31: =Statements!I29-Statements!I28-Statements!I27+Statements!I25 -> 0 | J31: =Statements!J29-Statements!J28-Statements!J27+Statements!J25 -> 0 | K31: =Statements!K29-Statements!K28-Statements!K27+Statements!K25 -> -1.2490009e-16 | L31: =Statements!L29-Statements!L28-Statements!L27+Statements!L25 -> 0 | M31: =Statements!M29-Statements!M28-Statements!M27+Statements!M25 -> 0 | ... T31: =Statements!T29-Statements!T28-Statements!T27+Statements!T25 -> 0
C32: Cash roll-forward | F32: =Statements!F48-Statements!F47-Statements!F46 -> 0 | G32: =Statements!G48-Statements!G47-Statements!G46 -> 5.5511151e-17 | H32: =Statements!H48-Statements!H47-Statements!H46 -> 0 | I32: =Statements!I48-Statements!I47-Statements!I46 -> 0 | J32: =Statements!J48-Statements!J47-Statements!J46 -> 0 | K32: =Statements!K48-Statements!K47-Statements!K46 -> 0 | L32: =Statements!L48-Statements!L47-Statements!L46 -> 0 | M32: =Statements!M48-Statements!M47-Statements!M46 -> 0 | ... T32: =Statements!T48-Statements!T47-Statements!T46 -> 0
C33: Retained earnings roll-forward | F33: =Statements!F70-Statements!E70-Statements!F21-Statements!F43 -> 2.220446e-16 | G33: =Statements!G70-Statements!F70-Statements!G21-Statements!G43 -> -1.6653345e-16 | H33: =Statements!H70-Statements!G70-Statements!H21-Statements!H43 -> 3.3306691e-16 | I33: =Statements!I70-Statements!H70-Statements!I21-Statements!I43 -> -5.5511151e-17 | J33: =Statements!J70-Statements!I70-Statements!J21-Statements!J43 -> -3.8857806e-16 | K33: =Statements!K70-Statements!J70-Statements!K21-Statements!K43 -> 0 | L33: =Statements!L70-Statements!K70-Statements!L21-Statements!L43 -> 3.3306691e-16 | M33: =Statements!M70-Statements!L70-Statements!M21-Statements!M43 -> 8.8817842e-16 | ... T33: =Statements!T70-Statements!S70-Statements!T21-Statements!T43 -> 5.3290705e-15
C36: Report reconciliation for base case
C37: Metric | E37: Workbook | F37: Report value | G37: Difference | H37: Basis
C38: FY27 revenue | E38: =Operating!E13 -> 6.06 | F38: 6.06 | G38: =IF(Assumptions!$E$5=2,E38-F38,"n.a.") -> 0 | H38: Base case only
C39: FY28 revenue | E39: =Operating!F13 -> 8.25 | F39: 8.25 | G39: =IF(Assumptions!$E$5=2,E39-F39,"n.a.") -> 0 | H39: Base case only
C40: FY31 revenue | E40: =Operating!I13 -> 25 | F40: 25 | G40: =IF(Assumptions!$E$5=2,E40-F40,"n.a.") -> 0 | H40: Base case only
C41: FY31 economic EBIT | E41: =Operating!I26 -> 9 | F41: 9 | G41: =IF(Assumptions!$E$5=2,E41-F41,"n.a.") -> 0 | H41: Base case only
C42: Target price | E42: =Comps!E23 -> 125 | F42: 125 | G42: =IF(Assumptions!$E$5=2,E42-F42,"n.a.") -> 0 | H42: Base case only
C43: Target-date DCF | E43: =DCF!E53 -> 89.634135 | F43: 89.634135 | G43: =IF(Assumptions!$E$5=2,E43-F43,"n.a.") -> 0 | H43: Base case only
C44: Net short notional return | E44: ='Short return'!E16 -> 0.39127305 | F44: 0.39127305 | G44: =IF(Assumptions!$E$5=2,E44-F44,"n.a.") -> -5.5511151e-17 | H44: Base case only
C45: Illustrative collateral XIRR | E45: ='Short return'!E20 -> 0.75259844 | F45: 0.75259845 | G45: =IF(Assumptions!$E$5=2,E45-F45,"n.a.") -> -1.1775382e-08 | H45: Base case only
